<?xml version="1.0"?>
<robot xmlns:xacro = "http://www.ros.org/wiki/xacro">  
    <xacro:include filename="$(find fishbot_description)/urdf/fishbot/common_inertia.xacro"/>  
    <xacro:macro name = "wheel_xacro" params = "wheel_name xyz">
        <!-- WHEEL -->
        <link name="${wheel_name}_link">
            <!-- 部件的外观 -->
            <visual>
                <origin xyz="0.0 0.0 0.0" rpy="1.57079 0.0 0.0"/>
                <geometry>
                <!-- 单位：m -->
                    <cylinder radius="0.032" length="0.04"/> 
                </geometry>
                <material name="yellow">
                    <color rgba="1.0 1.0 0.0 0.8"/>
                </material>
            </visual>
            <collision>
                <origin xyz="0.0 0.0 0.0" rpy="1.57079 0.0 0.0"/>
                <geometry>
                <!-- 单位：m -->
                    <cylinder radius="0.032" length="0.04"/> 
                </geometry>
                <material name="yellow">
                    <color rgba="1.0 1.0 0.0 0.8"/>
                </material>
            </collision>
            <xacro:cylinder_inertia m="0.05" r="0.032" h="0.04"/>
        </link>
        <!-- 机器人关节，用于组合机器人部件 -->
        <joint name="${wheel_name}_joint" type="continuous">
            <origin xyz="${xyz}" rpy="0.0 0.0 0.0"/>
            <parent link="base_link"/>
            <child link="${wheel_name}_link"/>
            <axis xyz="0.0 1.0 0.0"/>
        </joint>

        <gazebo reference="${wheel_name}_link">
            <mu1 value="20.0"/>
            <mu2 value="20.0"/>
            <kp value="1000000000.0"/>
            <kd value="1.0"/>
        </gazebo>
    </xacro:macro>
</robot>    